Workbook
Name Slicer_Department: #N/A
Name Slicer_Priority_Level: #N/A
Name Slicer_Task_Type: #N/A

Sheet raw_data
A1: Workflow_ID | B1: Process_Name | C1: Task_ID | D1: Task_Type | E1: Priority_Level | F1: Department | G1: Assigned_Employee_ID | H1: Task_Start_Time | I1: Task_End_Time | J1: Estimated_Time_Minutes | K1: Actual_Time_Minutes | L1: Delay_Flag | M1: Approval_Level | N1: Employee_Workload | O1: Cost_Per_Task
A2: WF_1 | B2: Customer Complaint | C2: TASK_1 | D2: Review | E2: Low | F2: Customer Service | G2: EMP_128 | H2: 45316.199 | I2: 45316.356 | J2: 208 | K2: 226 | L2: 1 | M2: Level 1 | N2: 1 | O2: 155.17
A3: WF_2 | B3: HR Onboarding | C3: TASK_2 | D3: Approval | E3: Low | F3: HR | G3: EMP_35 | H3: 45436.123 | I3: 45436.263 | J3: 194 | K3: 202 | L3: 1 | M3: Level 2 | N3: 5 | O3: 231.54
A4: WF_3 | B4: Invoice Approval | C4: TASK_3 | D4: Review | E4: High | F4: Finance | G4: EMP_88 | H4: 45373.149 | I4: 45373.369 | J4: 214 | K4: 317 | L4: 1 | M4: Level 1 | N4: 8 | O4: 280.95
A5: WF_4 | B5: Customer Complaint | C5: TASK_4 | D5: Review | E5: Medium | F5: Operations | G5: EMP_133 | H5: 45453.442 | I5: 45453.567 | J5: 176 | K5: 179 | L5: 1 | M5: Level 3 | N5: 1 | O5: 413.74
A6: WF_5 | B6: Customer Complaint | C6: TASK_5 | D6: Escalation | E6: Medium | F6: Finance | G6: EMP_80 | H6: 45475.485 | I6: 45475.65 | J6: 197 | K6: 238 | L6: 1 | M6: Level 3 | N6: 3 | O6: 152.3
A7: WF_6 | B7: Customer Complaint | C7: TASK_6 | D7: Validation | E7: Low | F7: Operations | G7: EMP_61 | H7: 45435.468 | I7: 45435.626 | J7: 199 | K7: 227 | L7: 1 | M7: Level 2 | N7: 5 | O7: 160.06
A8: WF_7 | B8: Purchase Order | C8: TASK_7 | D8: Escalation | E8: Medium | F8: Customer Service | G8: EMP_55 | H8: 45470.89 | I8: 45470.968 | J8: 84 | K8: 113 | L8: 1 | M8: Level 3 | N8: 6 | O8: 440.88
A9: WF_8 | B9: Purchase Order | C9: TASK_8 | D9: Data Entry | E9: Low | F9: IT | G9: EMP_42 | H9: 45517.322 | I9: 45517.49 | J9: 204 | K9: 241 | L9: 1 | M9: Level 1 | N9: 4 | O9: 406.61
A10: WF_9 | B10: Purchase Order | C10: TASK_9 | D10: Escalation | E10: Low | F10: Customer Service | G10: EMP_21 | H10: 45653.893 | I10: 45654.015 | J10: 59 | K10: 176 | L10: 1 | M10: Level 3 | N10: 2 | O10: 180.92
A11: WF_10 | B11: IT Support Ticket | C11: TASK_10 | D11: Approval | E11: High | F11: Operations | G11: EMP_2 | H11: 45460.051 | I11: 45460.109 | J11: 23 | K11: 83 | L11: 1 | M11: Level 3 | N11: 1 | O11: 313.09
A12: WF_11 | B12: Customer Complaint | C12: TASK_11 | D12: Approval | E12: Medium | F12: Finance | G12: EMP_140 | H12: 45488.07 | I12: 45488.24 | J12: 235 | K12: 244 | L12: 1 | M12: Level 2 | N12: 9 | O12: 290.34
A13: WF_12 | B13: HR Onboarding | C13: TASK_12 | D13: Approval | E13: Medium | F13: Finance | G13: EMP_133 | H13: 45401.915 | I13: 45402.033 | J13: 167 | K13: 170 | L13: 1 | M13: Level 1 | N13: 3 | O13: 428.89
... A2501: WF_2500 | B2501: IT Support Ticket | C2501: TASK_2500 | D2501: Data Entry | E2501: Medium | F2501: Finance | G2501: EMP_63 | H2501: 45324.069 | I2501: 45324.136 | J2501: 89 | K2501: 96 | L2501: 1 | M2501: Level 3 | N2501: 7 | O2501: 274.87

Sheet calculated_columns
A1: Workflow_ID | B1: Process_Name | C1: Task_ID | D1: Task_Type | E1: Priority_Level | F1: Department | G1: Assigned_Employee_ID | H1: Task_Start_Time | I1: Task_End_Time | J1: Estimated_Time_Minutes | K1: Actual_Time_Minutes | L1: Delay_Flag | M1: Approval_Level | N1: Employee_Workload | O1: Cost_Per_Task | P1: Time_Overrun | Q1: Efficiency_Ratio | R1: Efficiency_Status | S1: Task_Duration | T1: Delay_Severity
A2: WF_1 | B2: Customer Complaint | C2: TASK_1 | D2: Review | E2: Low | F2: Customer Service | G2: EMP_128 | H2: 45316.199 | I2: 45316.356 | J2: 208 | K2: 226 | L2: 1 | M2: Level 1 | N2: 1 | O2: 155.17 | P2: =K2-J2 -> 18 | Q2: =J2/K2 -> 0.92035398 | R2: =IF(Q2>1,"Efficient", IF(Q2=1,"On Target","Inefficient")) -> Inefficient | S2: =IF(K2<30,"Short", IF(K2<60,"Medium", IF(K2<120,"Long","Very Long"))) -> Very Long | T2: =IF(K2<=J2,"On Time", IF(K2-J2<=30,"Minor Delay","Major Delay")) -> Minor Delay
A3: WF_2 | B3: HR Onboarding | C3: TASK_2 | D3: Approval | E3: Low | F3: HR | G3: EMP_35 | H3: 45436.123 | I3: 45436.263 | J3: 194 | K3: 202 | L3: 1 | M3: Level 2 | N3: 5 | O3: 231.54 | P3: =K3-J3 -> 8 | Q3: =J3/K3 -> 0.96039604 | R3: =IF(Q3>1,"Efficient", IF(Q3=1,"On Target","Inefficient")) -> Inefficient | S3: =IF(K3<30,"Short", IF(K3<60,"Medium", IF(K3<120,"Long","Very Long"))) -> Very Long | T3: =IF(K3<=J3,"On Time", IF(K3-J3<=30,"Minor Delay","Major Delay")) -> Minor Delay
A4: WF_3 | B4: Invoice Approval | C4: TASK_3 | D4: Review | E4: High | F4: Finance | G4: EMP_88 | H4: 45373.149 | I4: 45373.369 | J4: 214 | K4: 317 | L4: 1 | M4: Level 1 | N4: 8 | O4: 280.95 | P4: =K4-J4 -> 103 | Q4: =J4/K4 -> 0.67507886 | R4: =IF(Q4>1,"Efficient", IF(Q4=1,"On Target","Inefficient")) -> Inefficient | S4: =IF(K4<30,"Short", IF(K4<60,"Medium", IF(K4<120,"Long","Very Long"))) -> Very Long | T4: =IF(K4<=J4,"On Time", IF(K4-J4<=30,"Minor Delay","Major Delay")) -> Major Delay
A5: WF_4 | B5: Customer Complaint | C5: TASK_4 | D5: Review | E5: Medium | F5: Operations | G5: EMP_133 | H5: 45453.442 | I5: 45453.567 | J5: 176 | K5: 179 | L5: 1 | M5: Level 3 | N5: 1 | O5: 413.74 | P5: =K5-J5 -> 3 | Q5: =J5/K5 -> 0.98324022 | R5: =IF(Q5>1,"Efficient", IF(Q5=1,"On Target","Inefficient")) -> Inefficient | S5: =IF(K5<30,"Short", IF(K5<60,"Medium", IF(K5<120,"Long","Very Long"))) -> Very Long | T5: =IF(K5<=J5,"On Time", IF(K5-J5<=30,"Minor Delay","Major Delay")) -> Minor Delay
A6: WF_5 | B6: Customer Complaint | C6: TASK_5 | D6: Escalation | E6: Medium | F6: Finance | G6: EMP_80 | H6: 45475.485 | I6: 45475.65 | J6: 197 | K6: 238 | L6: 1 | M6: Level 3 | N6: 3 | O6: 152.3 | P6: =K6-J6 -> 41 | Q6: =J6/K6 -> 0.82773109 | R6: =IF(Q6>1,"Efficient", IF(Q6=1,"On Target","Inefficient")) -> Inefficient | S6: =IF(K6<30,"Short", IF(K6<60,"Medium", IF(K6<120,"Long","Very Long"))) -> Very Long | T6: =IF(K6<=J6,"On Time", IF(K6-J6<=30,"Minor Delay","Major Delay")) -> Major Delay
A7: WF_6 | B7: Customer Complaint | C7: TASK_6 | D7: Validation | E7: Low | F7: Operations | G7: EMP_61 | H7: 45435.468 | I7: 45435.626 | J7: 199 | K7: 227 | L7: 1 | M7: Level 2 | N7: 5 | O7: 160.06 | P7: =K7-J7 -> 28 | Q7: =J7/K7 -> 0.87665198 | R7: =IF(Q7>1,"Efficient", IF(Q7=1,"On Target","Inefficient")) -> Inefficient | S7: =IF(K7<30,"Short", IF(K7<60,"Medium", IF(K7<120,"Long","Very Long"))) -> Very Long | T7: =IF(K7<=J7,"On Time", IF(K7-J7<=30,"Minor Delay","Major Delay")) -> Minor Delay
A8: WF_7 | B8: Purchase Order | C8: TASK_7 | D8: Escalation | E8: Medium | F8: Customer Service | G8: EMP_55 | H8: 45470.89 | I8: 45470.968 | J8: 84 | K8: 113 | L8: 1 | M8: Level 3 | N8: 6 | O8: 440.88 | P8: =K8-J8 -> 29 | Q8: =J8/K8 -> 0.74336283 | R8: =IF(Q8>1,"Efficient", IF(Q8=1,"On Target","Inefficient")) -> Inefficient | S8: =IF(K8<30,"Short", IF(K8<60,"Medium", IF(K8<120,"Long","Very Long"))) -> Long | T8: =IF(K8<=J8,"On Time", IF(K8-J8<=30,"Minor Delay","Major Delay")) -> Minor Delay
A9: WF_8 | B9: Purchase Order | C9: TASK_8 | D9: Data Entry | E9: Low | F9: IT | G9: EMP_42 | H9: 45517.322 | I9: 45517.49 | J9: 204 | K9: 241 | L9: 1 | M9: Level 1 | N9: 4 | O9: 406.61 | P9: =K9-J9 -> 37 | Q9: =J9/K9 -> 0.84647303 | R9: =IF(Q9>1,"Efficient", IF(Q9=1,"On Target","Inefficient")) -> Inefficient | S9: =IF(K9<30,"Short", IF(K9<60,"Medium", IF(K9<120,"Long","Very Long"))) -> Very Long | T9: =IF(K9<=J9,"On Time", IF(K9-J9<=30,"Minor Delay","Major Delay")) -> Major Delay
A10: WF_9 | B10: Purchase Order | C10: TASK_9 | D10: Escalation | E10: Low | F10: Customer Service | G10: EMP_21 | H10: 45653.893 | I10: 45654.015 | J10: 59 | K10: 176 | L10: 1 | M10: Level 3 | N10: 2 | O10: 180.92 | P10: =K10-J10 -> 117 | Q10: =J10/K10 -> 0.33522727 | R10: =IF(Q10>1,"Efficient", IF(Q10=1,"On Target","Inefficient")) -> Inefficient | S10: =IF(K10<30,"Short", IF(K10<60,"Medium", IF(K10<120,"Long","Very Long"))) -> Very Long | T10: =IF(K10<=J10,"On Time", IF(K10-J10<=30,"Minor Delay","Major Delay")) -> Major Delay
A11: WF_10 | B11: IT Support Ticket | C11: TASK_10 | D11: Approval | E11: High | F11: Operations | G11: EMP_2 | H11: 45460.051 | I11: 45460.109 | J11: 23 | K11: 83 | L11: 1 | M11: Level 3 | N11: 1 | O11: 313.09 | P11: =K11-J11 -> 60 | Q11: =J11/K11 -> 0.27710843 | R11: =IF(Q11>1,"Efficient", IF(Q11=1,"On Target","Inefficient")) -> Inefficient | S11: =IF(K11<30,"Short", IF(K11<60,"Medium", IF(K11<120,"Long","Very Long"))) -> Long | T11: =IF(K11<=J11,"On Time", IF(K11-J11<=30,"Minor Delay","Major Delay")) -> Major Delay
A12: WF_11 | B12: Customer Complaint | C12: TASK_11 | D12: Approval | E12: Medium | F12: Finance | G12: EMP_140 | H12: 45488.07 | I12: 45488.24 | J12: 235 | K12: 244 | L12: 1 | M12: Level 2 | N12: 9 | O12: 290.34 | P12: =K12-J12 -> 9 | Q12: =J12/K12 -> 0.96311475 | R12: =IF(Q12>1,"Efficient", IF(Q12=1,"On Target","Inefficient")) -> Inefficient | S12: =IF(K12<30,"Short", IF(K12<60,"Medium", IF(K12<120,"Long","Very Long"))) -> Very Long | T12: =IF(K12<=J12,"On Time", IF(K12-J12<=30,"Minor Delay","Major Delay")) -> Minor Delay
A13: WF_12 | B13: HR Onboarding | C13: TASK_12 | D13: Approval | E13: Medium | F13: Finance | G13: EMP_133 | H13: 45401.915 | I13: 45402.033 | J13: 167 | K13: 170 | L13: 1 | M13: Level 1 | N13: 3 | O13: 428.89 | P13: =K13-J13 -> 3 | Q13: =J13/K13 -> 0.98235294 | R13: =IF(Q13>1,"Efficient", IF(Q13=1,"On Target","Inefficient")) -> Inefficient | S13: =IF(K13<30,"Short", IF(K13<60,"Medium", IF(K13<120,"Long","Very Long"))) -> Very Long | T13: =IF(K13<=J13,"On Time", IF(K13-J13<=30,"Minor Delay","Major Delay")) -> Minor Delay
... A2501: WF_2500 | B2501: IT Support Ticket | C2501: TASK_2500 | D2501: Data Entry | E2501: Medium | F2501: Finance | G2501: EMP_63 | H2501: 45324.069 | I2501: 45324.136 | J2501: 89 | K2501: 96 | L2501: 1 | M2501: Level 3 | N2501: 7 | O2501: 274.87 | P2501: =K2501-J2501 -> 7 | Q2501: =J2501/K2501 -> 0.92708333 | R2501: =IF(Q2501>1,"Efficient", IF(Q2501=1,"On Target","Inefficient")) -> Inefficient | S2501: =IF(K2501<30,"Short", IF(K2501<60,"Medium", IF(K2501<120,"Long","Very Long"))) -> Long | T2501: =IF(K2501<=J2501,"On Time", IF(K2501-J2501<=30,"Minor Delay","Major Delay")) -> Minor Delay

Sheet pivot_tables
A2: Process Performance | F2: Task Type Analysis
A3: Process_Name | B3: Count of Task_ID | C3: Average of Delay_Flag | F3: Task_Type | G3: Average of Actual_Time_Minutes | H3: Average of Delay_Flag
A4: Customer Complaint | B4: 501 | C4: 0.94810379 | F4: Approval | G4: 178.51116 | H4: 0.94117647
A5: HR Onboarding | B5: 510 | C5: 0.94117647 | F5: Data Entry | G5: 180.39583 | H5: 0.95208333
A6: Invoice Approval | B6: 480 | C6: 0.9625 | F6: Escalation | G6: 179.43452 | H6: 0.94246032
A7: IT Support Ticket | B7: 492 | C7: 0.94105691 | F7: Review | G7: 180.6 | H7: 0.9490566
A8: Purchase Order | B8: 517 | C8: 0.95357834 | F8: Validation | G8: 185.41785 | H8: 0.96146045
A9: Grand Total | B9: 2500 | C9: 0.9492 | F9: Grand Total | G9: 180.864 | H9: 0.9492
A11: Department Performance | F11: Approval Level Bottleneck Analysis
A12: Department | B12: Count of Task_ID | C12: Average of Delay_Flag | D12: Average of Cost_Per_Task | F12: Approval_Level | G12: Average of Actual_Time_Minutes | H12: Average of Delay_Flag
A13: Customer Service | B13: 492 | C13: 0.93902439 | D13: 273.90437 | F13: Level 1 | G13: 180.77724 | H13: 0.96004843
A14: Finance | B14: 504 | C14: 0.95238095 | D14: 275.0655 | F14: Level 2 | G14: 180.4458 | H14: 0.94640682
A15: HR | B15: 502 | C15: 0.95219124 | D15: 277.11066 | F15: Level 3 | G15: 181.35053 | H15: 0.94138335
A16: IT | B16: 497 | C16: 0.95372233 | D16: 283.00704 | F16: Grand Total | G16: 180.864 | H16: 0.9492
A17: Operations | B17: 505 | C17: 0.94851485 | D17: 280.75992
A18: Grand Total | B18: 2500 | C18: 0.9492 | D18: 277.97671
A20: Workload vs Delay
A21: Employee_Workload | B21: Average of Delay_Flag
A22: 1 | B22: 0.96428571
A23: 2 | B23: 0.95217391
A24: 3 | B24: 0.92916667
A25: 4 | B25: 0.968
A26: 5 | B26: 0.94833948
A27: 6 | B27: 0.94186047
A28: 7 | B28: 0.94901961
A29: 8 | B29: 0.95238095
A30: 9 | B30: 0.93333333
A31: 10 | B31: 0.9535865
A32: Grand Total | B32: 0.9492

Sheet Sheet2
D2: Total Tasks | E2: Total Delays | F2: Delay Rate | G2: Avg Completion Time | H2: Avg Cost Per Task
A3: Row Labels | B3: Average of Delay_Flag | D3: =COUNTA(calculated_columns!C2:C2501) -> 2500 | E3: =SUM(calculated_columns!L2:L2501) -> 2373 | F3: =SUM(calculated_columns!L2:L2501)/COUNTA(calculated_columns!C2:C2501) -> 0.9492 | G3: =AVERAGE(calculated_columns!K2:K2501) -> 180.864 | H3: =AVERAGE(calculated_columns!O2:O2501) -> 277.97671
A4: Customer Complaint | B4: 0.94810379
A5: HR Onboarding | B5: 0.94117647
A6: Invoice Approval | B6: 0.9625
A7: IT Support Ticket | B7: 0.94105691
A8: Purchase Order | B8: 0.95357834
A9: Grand Total | B9: 0.9492
A12: Row Labels | B12: Average of Actual_Time_Minutes
A13: Approval | B13: 178.51116
A14: Data Entry | B14: 180.39583
A15: Escalation | B15: 179.43452
A16: Review | B16: 180.6
A17: Validation | B17: 185.41785
A18: Grand Total | B18: 180.864
A21: Row Labels | B21: Average of Delay_Flag
A22: 1 | B22: 0.96428571
A23: 2 | B23: 0.95217391
A24: 3 | B24: 0.92916667
A25: 4 | B25: 0.968
A26: 5 | B26: 0.94833948
A27: 6 | B27: 0.94186047
A28: 7 | B28: 0.94901961
A29: 8 | B29: 0.95238095
A30: 9 | B30: 0.93333333
A31: 10 | B31: 0.9535865
A32: Grand Total | B32: 0.9492
A35: Row Labels | B35: Sum of Cost_Per_Task
A36: Customer Service | B36: 134760.95
A37: Finance | B37: 138633.01
A38: HR | B38: 139109.55
A39: IT | B39: 140654.5
A40: Operations | B40: 141783.76
A41: Grand Total | B41: 694941.77
A44: Row Labels | B44: Count of Task_ID
A45: Approval | B45: 493
A46: Data Entry | B46: 480
A47: Escalation | B47: 504
A48: Review | B48: 530
A49: Validation | B49: 493
...

Sheet operations_performance_dashboar
